Workbook
Name payout_mult: picks!$Q$1

Sheet _raw
A1: scraped_at | B1: projection_id | C1: league | D1: sport | E1: player | F1: team | G1: position | H1: description | I1: stat_type | J1: line | K1: start_time | L1: odds_type

Sheet picks
A1: projection_id | B1: player | C1: team | D1: league | E1: stat_type | F1: line | G1: pick (over/under) | H1: your_prob | I1: break_even | J1: edge | K1: half_kelly | L1: grade | M1: notes | P1: payout_mult ↓ | Q1: 3
B2: =IFERROR(VLOOKUP(A2,_raw!B:L,4,FALSE),"") | C2: =IFERROR(VLOOKUP(A2,_raw!B:L,5,FALSE),"") | D2: =IFERROR(VLOOKUP(A2,_raw!B:L,2,FALSE),"") | E2: =IFERROR(VLOOKUP(A2,_raw!B:L,8,FALSE),"") | F2: =IFERROR(VLOOKUP(A2,_raw!B:L,9,FALSE),"") | I2: =IF(payout_mult="","",SQRT(1/payout_mult)) | J2: =IF(OR(H2="",I2=""),"",H2-I2) | K2: =IFERROR(IF(OR(H2="",J2<=0),0,MIN(0.25,MAX(0,(H2*(payout_mult^(1/2)-1)-(1-H2))/(payout_mult^(1/2)-1)/2))),0) | L2: =IF(J2="","",IF(J2>=0.10,"A+",IF(J2>=0.07,"A",IF(J2>=0.04,"B",IF(J2>=0.02,"C",IF(J2>0,"D","F")))))) | P2: 2-pick=3 · 3-pick=5 · 4-pick=10 · 5-pick=20 · 6-pick=25
B3: =IFERROR(VLOOKUP(A3,_raw!B:L,4,FALSE),"") | C3: =IFERROR(VLOOKUP(A3,_raw!B:L,5,FALSE),"") | D3: =IFERROR(VLOOKUP(A3,_raw!B:L,2,FALSE),"") | E3: =IFERROR(VLOOKUP(A3,_raw!B:L,8,FALSE),"") | F3: =IFERROR(VLOOKUP(A3,_raw!B:L,9,FALSE),"") | I3: =IF(payout_mult="","",SQRT(1/payout_mult)) | J3: =IF(OR(H3="",I3=""),"",H3-I3) | K3: =IFERROR(IF(OR(H3="",J3<=0),0,MIN(0.25,MAX(0,(H3*(payout_mult^(1/2)-1)-(1-H3))/(payout_mult^(1/2)-1)/2))),0) | L3: =IF(J3="","",IF(J3>=0.10,"A+",IF(J3>=0.07,"A",IF(J3>=0.04,"B",IF(J3>=0.02,"C",IF(J3>0,"D","F"))))))
B4: =IFERROR(VLOOKUP(A4,_raw!B:L,4,FALSE),"") | C4: =IFERROR(VLOOKUP(A4,_raw!B:L,5,FALSE),"") | D4: =IFERROR(VLOOKUP(A4,_raw!B:L,2,FALSE),"") | E4: =IFERROR(VLOOKUP(A4,_raw!B:L,8,FALSE),"") | F4: =IFERROR(VLOOKUP(A4,_raw!B:L,9,FALSE),"") | I4: =IF(payout_mult="","",SQRT(1/payout_mult)) | J4: =IF(OR(H4="",I4=""),"",H4-I4) | K4: =IFERROR(IF(OR(H4="",J4<=0),0,MIN(0.25,MAX(0,(H4*(payout_mult^(1/2)-1)-(1-H4))/(payout_mult^(1/2)-1)/2))),0) | L4: =IF(J4="","",IF(J4>=0.10,"A+",IF(J4>=0.07,"A",IF(J4>=0.04,"B",IF(J4>=0.02,"C",IF(J4>0,"D","F"))))))
B5: =IFERROR(VLOOKUP(A5,_raw!B:L,4,FALSE),"") | C5: =IFERROR(VLOOKUP(A5,_raw!B:L,5,FALSE),"") | D5: =IFERROR(VLOOKUP(A5,_raw!B:L,2,FALSE),"") | E5: =IFERROR(VLOOKUP(A5,_raw!B:L,8,FALSE),"") | F5: =IFERROR(VLOOKUP(A5,_raw!B:L,9,FALSE),"") | I5: =IF(payout_mult="","",SQRT(1/payout_mult)) | J5: =IF(OR(H5="",I5=""),"",H5-I5) | K5: =IFERROR(IF(OR(H5="",J5<=0),0,MIN(0.25,MAX(0,(H5*(payout_mult^(1/2)-1)-(1-H5))/(payout_mult^(1/2)-1)/2))),0) | L5: =IF(J5="","",IF(J5>=0.10,"A+",IF(J5>=0.07,"A",IF(J5>=0.04,"B",IF(J5>=0.02,"C",IF(J5>0,"D","F"))))))
B6: =IFERROR(VLOOKUP(A6,_raw!B:L,4,FALSE),"") | C6: =IFERROR(VLOOKUP(A6,_raw!B:L,5,FALSE),"") | D6: =IFERROR(VLOOKUP(A6,_raw!B:L,2,FALSE),"") | E6: =IFERROR(VLOOKUP(A6,_raw!B:L,8,FALSE),"") | F6: =IFERROR(VLOOKUP(A6,_raw!B:L,9,FALSE),"") | I6: =IF(payout_mult="","",SQRT(1/payout_mult)) | J6: =IF(OR(H6="",I6=""),"",H6-I6) | K6: =IFERROR(IF(OR(H6="",J6<=0),0,MIN(0.25,MAX(0,(H6*(payout_mult^(1/2)-1)-(1-H6))/(payout_mult^(1/2)-1)/2))),0) | L6: =IF(J6="","",IF(J6>=0.10,"A+",IF(J6>=0.07,"A",IF(J6>=0.04,"B",IF(J6>=0.02,"C",IF(J6>0,"D","F"))))))
B7: =IFERROR(VLOOKUP(A7,_raw!B:L,4,FALSE),"") | C7: =IFERROR(VLOOKUP(A7,_raw!B:L,5,FALSE),"") | D7: =IFERROR(VLOOKUP(A7,_raw!B:L,2,FALSE),"") | E7: =IFERROR(VLOOKUP(A7,_raw!B:L,8,FALSE),"") | F7: =IFERROR(VLOOKUP(A7,_raw!B:L,9,FALSE),"") | I7: =IF(payout_mult="","",SQRT(1/payout_mult)) | J7: =IF(OR(H7="",I7=""),"",H7-I7) | K7: =IFERROR(IF(OR(H7="",J7<=0),0,MIN(0.25,MAX(0,(H7*(payout_mult^(1/2)-1)-(1-H7))/(payout_mult^(1/2)-1)/2))),0) | L7: =IF(J7="","",IF(J7>=0.10,"A+",IF(J7>=0.07,"A",IF(J7>=0.04,"B",IF(J7>=0.02,"C",IF(J7>0,"D","F"))))))
B8: =IFERROR(VLOOKUP(A8,_raw!B:L,4,FALSE),"") | C8: =IFERROR(VLOOKUP(A8,_raw!B:L,5,FALSE),"") | D8: =IFERROR(VLOOKUP(A8,_raw!B:L,2,FALSE),"") | E8: =IFERROR(VLOOKUP(A8,_raw!B:L,8,FALSE),"") | F8: =IFERROR(VLOOKUP(A8,_raw!B:L,9,FALSE),"") | I8: =IF(payout_mult="","",SQRT(1/payout_mult)) | J8: =IF(OR(H8="",I8=""),"",H8-I8) | K8: =IFERROR(IF(OR(H8="",J8<=0),0,MIN(0.25,MAX(0,(H8*(payout_mult^(1/2)-1)-(1-H8))/(payout_mult^(1/2)-1)/2))),0) | L8: =IF(J8="","",IF(J8>=0.10,"A+",IF(J8>=0.07,"A",IF(J8>=0.04,"B",IF(J8>=0.02,"C",IF(J8>0,"D","F"))))))
B9: =IFERROR(VLOOKUP(A9,_raw!B:L,4,FALSE),"") | C9: =IFERROR(VLOOKUP(A9,_raw!B:L,5,FALSE),"") | D9: =IFERROR(VLOOKUP(A9,_raw!B:L,2,FALSE),"") | E9: =IFERROR(VLOOKUP(A9,_raw!B:L,8,FALSE),"") | F9: =IFERROR(VLOOKUP(A9,_raw!B:L,9,FALSE),"") | I9: =IF(payout_mult="","",SQRT(1/payout_mult)) | J9: =IF(OR(H9="",I9=""),"",H9-I9) | K9: =IFERROR(IF(OR(H9="",J9<=0),0,MIN(0.25,MAX(0,(H9*(payout_mult^(1/2)-1)-(1-H9))/(payout_mult^(1/2)-1)/2))),0) | L9: =IF(J9="","",IF(J9>=0.10,"A+",IF(J9>=0.07,"A",IF(J9>=0.04,"B",IF(J9>=0.02,"C",IF(J9>0,"D","F"))))))
B10: =IFERROR(VLOOKUP(A10,_raw!B:L,4,FALSE),"") | C10: =IFERROR(VLOOKUP(A10,_raw!B:L,5,FALSE),"") | D10: =IFERROR(VLOOKUP(A10,_raw!B:L,2,FALSE),"") | E10: =IFERROR(VLOOKUP(A10,_raw!B:L,8,FALSE),"") | F10: =IFERROR(VLOOKUP(A10,_raw!B:L,9,FALSE),"") | I10: =IF(payout_mult="","",SQRT(1/payout_mult)) | J10: =IF(OR(H10="",I10=""),"",H10-I10) | K10: =IFERROR(IF(OR(H10="",J10<=0),0,MIN(0.25,MAX(0,(H10*(payout_mult^(1/2)-1)-(1-H10))/(payout_mult^(1/2)-1)/2))),0) | L10: =IF(J10="","",IF(J10>=0.10,"A+",IF(J10>=0.07,"A",IF(J10>=0.04,"B",IF(J10>=0.02,"C",IF(J10>0,"D","F"))))))
B11: =IFERROR(VLOOKUP(A11,_raw!B:L,4,FALSE),"") | C11: =IFERROR(VLOOKUP(A11,_raw!B:L,5,FALSE),"") | D11: =IFERROR(VLOOKUP(A11,_raw!B:L,2,FALSE),"") | E11: =IFERROR(VLOOKUP(A11,_raw!B:L,8,FALSE),"") | F11: =IFERROR(VLOOKUP(A11,_raw!B:L,9,FALSE),"") | I11: =IF(payout_mult="","",SQRT(1/payout_mult)) | J11: =IF(OR(H11="",I11=""),"",H11-I11) | K11: =IFERROR(IF(OR(H11="",J11<=0),0,MIN(0.25,MAX(0,(H11*(payout_mult^(1/2)-1)-(1-H11))/(payout_mult^(1/2)-1)/2))),0) | L11: =IF(J11="","",IF(J11>=0.10,"A+",IF(J11>=0.07,"A",IF(J11>=0.04,"B",IF(J11>=0.02,"C",IF(J11>0,"D","F"))))))
B12: =IFERROR(VLOOKUP(A12,_raw!B:L,4,FALSE),"") | C12: =IFERROR(VLOOKUP(A12,_raw!B:L,5,FALSE),"") | D12: =IFERROR(VLOOKUP(A12,_raw!B:L,2,FALSE),"") | E12: =IFERROR(VLOOKUP(A12,_raw!B:L,8,FALSE),"") | F12: =IFERROR(VLOOKUP(A12,_raw!B:L,9,FALSE),"") | I12: =IF(payout_mult="","",SQRT(1/payout_mult)) | J12: =IF(OR(H12="",I12=""),"",H12-I12) | K12: =IFERROR(IF(OR(H12="",J12<=0),0,MIN(0.25,MAX(0,(H12*(payout_mult^(1/2)-1)-(1-H12))/(payout_mult^(1/2)-1)/2))),0) | L12: =IF(J12="","",IF(J12>=0.10,"A+",IF(J12>=0.07,"A",IF(J12>=0.04,"B",IF(J12>=0.02,"C",IF(J12>0,"D","F"))))))
B13: =IFERROR(VLOOKUP(A13,_raw!B:L,4,FALSE),"") | C13: =IFERROR(VLOOKUP(A13,_raw!B:L,5,FALSE),"") | D13: =IFERROR(VLOOKUP(A13,_raw!B:L,2,FALSE),"") | E13: =IFERROR(VLOOKUP(A13,_raw!B:L,8,FALSE),"") | F13: =IFERROR(VLOOKUP(A13,_raw!B:L,9,FALSE),"") | I13: =IF(payout_mult="","",SQRT(1/payout_mult)) | J13: =IF(OR(H13="",I13=""),"",H13-I13) | K13: =IFERROR(IF(OR(H13="",J13<=0),0,MIN(0.25,MAX(0,(H13*(payout_mult^(1/2)-1)-(1-H13))/(payout_mult^(1/2)-1)/2))),0) | L13: =IF(J13="","",IF(J13>=0.10,"A+",IF(J13>=0.07,"A",IF(J13>=0.04,"B",IF(J13>=0.02,"C",IF(J13>0,"D","F"))))))
B14: =IFERROR(VLOOKUP(A14,_raw!B:L,4,FALSE),"") | C14: =IFERROR(VLOOKUP(A14,_raw!B:L,5,FALSE),"") | D14: =IFERROR(VLOOKUP(A14,_raw!B:L,2,FALSE),"") | E14: =IFERROR(VLOOKUP(A14,_raw!B:L,8,FALSE),"") | F14: =IFERROR(VLOOKUP(A14,_raw!B:L,9,FALSE),"") | I14: =IF(payout_mult="","",SQRT(1/payout_mult)) | J14: =IF(OR(H14="",I14=""),"",H14-I14) | K14: =IFERROR(IF(OR(H14="",J14<=0),0,MIN(0.25,MAX(0,(H14*(payout_mult^(1/2)-1)-(1-H14))/(payout_mult^(1/2)-1)/2))),0) | L14: =IF(J14="","",IF(J14>=0.10,"A+",IF(J14>=0.07,"A",IF(J14>=0.04,"B",IF(J14>=0.02,"C",IF(J14>0,"D","F"))))))
... B50: =IFERROR(VLOOKUP(A50,_raw!B:L,4,FALSE),"") | C50: =IFERROR(VLOOKUP(A50,_raw!B:L,5,FALSE),"") | D50: =IFERROR(VLOOKUP(A50,_raw!B:L,2,FALSE),"") | E50: =IFERROR(VLOOKUP(A50,_raw!B:L,8,FALSE),"") | F50: =IFERROR(VLOOKUP(A50,_raw!B:L,9,FALSE),"") | I50: =IF(payout_mult="","",SQRT(1/payout_mult)) | J50: =IF(OR(H50="",I50=""),"",H50-I50) | K50: =IFERROR(IF(OR(H50="",J50<=0),0,MIN(0.25,MAX(0,(H50*(payout_mult^(1/2)-1)-(1-H50))/(payout_mult^(1/2)-1)/2))),0) | L50: =IF(J50="","",IF(J50>=0.10,"A+",IF(J50>=0.07,"A",IF(J50>=0.04,"B",IF(J50>=0.02,"C",IF(J50>0,"D","F"))))))

Sheet tracking
A1: projection_id | B1: player | C1: stat_type | D1: line | E1: pick | F1: actual | G1: hit | H1: units_risked | I1: pl_units | J1: note
G2: =IF(F2="","",IF(E2="over",IF(F2>D2,1,IF(F2<D2,0,"push")),IF(F2<D2,1,IF(F2>D2,0,"push")))) | I2: =IF(G2="push",0,IF(G2=1,H2*(picks!Q1^(1/2)-1),IF(G2=0,-H2,"")))
G3: =IF(F3="","",IF(E3="over",IF(F3>D3,1,IF(F3<D3,0,"push")),IF(F3<D3,1,IF(F3>D3,0,"push")))) | I3: =IF(G3="push",0,IF(G3=1,H3*(picks!Q1^(1/2)-1),IF(G3=0,-H3,"")))
G4: =IF(F4="","",IF(E4="over",IF(F4>D4,1,IF(F4<D4,0,"push")),IF(F4<D4,1,IF(F4>D4,0,"push")))) | I4: =IF(G4="push",0,IF(G4=1,H4*(picks!Q1^(1/2)-1),IF(G4=0,-H4,"")))
G5: =IF(F5="","",IF(E5="over",IF(F5>D5,1,IF(F5<D5,0,"push")),IF(F5<D5,1,IF(F5>D5,0,"push")))) | I5: =IF(G5="push",0,IF(G5=1,H5*(picks!Q1^(1/2)-1),IF(G5=0,-H5,"")))
G6: =IF(F6="","",IF(E6="over",IF(F6>D6,1,IF(F6<D6,0,"push")),IF(F6<D6,1,IF(F6>D6,0,"push")))) | I6: =IF(G6="push",0,IF(G6=1,H6*(picks!Q1^(1/2)-1),IF(G6=0,-H6,"")))
G7: =IF(F7="","",IF(E7="over",IF(F7>D7,1,IF(F7<D7,0,"push")),IF(F7<D7,1,IF(F7>D7,0,"push")))) | I7: =IF(G7="push",0,IF(G7=1,H7*(picks!Q1^(1/2)-1),IF(G7=0,-H7,"")))
G8: =IF(F8="","",IF(E8="over",IF(F8>D8,1,IF(F8<D8,0,"push")),IF(F8<D8,1,IF(F8>D8,0,"push")))) | I8: =IF(G8="push",0,IF(G8=1,H8*(picks!Q1^(1/2)-1),IF(G8=0,-H8,"")))
G9: =IF(F9="","",IF(E9="over",IF(F9>D9,1,IF(F9<D9,0,"push")),IF(F9<D9,1,IF(F9>D9,0,"push")))) | I9: =IF(G9="push",0,IF(G9=1,H9*(picks!Q1^(1/2)-1),IF(G9=0,-H9,"")))
G10: =IF(F10="","",IF(E10="over",IF(F10>D10,1,IF(F10<D10,0,"push")),IF(F10<D10,1,IF(F10>D10,0,"push")))) | I10: =IF(G10="push",0,IF(G10=1,H10*(picks!Q1^(1/2)-1),IF(G10=0,-H10,"")))
G11: =IF(F11="","",IF(E11="over",IF(F11>D11,1,IF(F11<D11,0,"push")),IF(F11<D11,1,IF(F11>D11,0,"push")))) | I11: =IF(G11="push",0,IF(G11=1,H11*(picks!Q1^(1/2)-1),IF(G11=0,-H11,"")))
G12: =IF(F12="","",IF(E12="over",IF(F12>D12,1,IF(F12<D12,0,"push")),IF(F12<D12,1,IF(F12>D12,0,"push")))) | I12: =IF(G12="push",0,IF(G12=1,H12*(picks!Q1^(1/2)-1),IF(G12=0,-H12,"")))
G13: =IF(F13="","",IF(E13="over",IF(F13>D13,1,IF(F13<D13,0,"push")),IF(F13<D13,1,IF(F13>D13,0,"push")))) | I13: =IF(G13="push",0,IF(G13=1,H13*(picks!Q1^(1/2)-1),IF(G13=0,-H13,"")))
G14: =IF(F14="","",IF(E14="over",IF(F14>D14,1,IF(F14<D14,0,"push")),IF(F14<D14,1,IF(F14>D14,0,"push")))) | I14: =IF(G14="push",0,IF(G14=1,H14*(picks!Q1^(1/2)-1),IF(G14=0,-H14,"")))
G15: =IF(F15="","",IF(E15="over",IF(F15>D15,1,IF(F15<D15,0,"push")),IF(F15<D15,1,IF(F15>D15,0,"push")))) | I15: =IF(G15="push",0,IF(G15=1,H15*(picks!Q1^(1/2)-1),IF(G15=0,-H15,"")))
G16: =IF(F16="","",IF(E16="over",IF(F16>D16,1,IF(F16<D16,0,"push")),IF(F16<D16,1,IF(F16>D16,0,"push")))) | I16: =IF(G16="push",0,IF(G16=1,H16*(picks!Q1^(1/2)-1),IF(G16=0,-H16,"")))
G17: =IF(F17="","",IF(E17="over",IF(F17>D17,1,IF(F17<D17,0,"push")),IF(F17<D17,1,IF(F17>D17,0,"push")))) | I17: =IF(G17="push",0,IF(G17=1,H17*(picks!Q1^(1/2)-1),IF(G17=0,-H17,"")))
G18: =IF(F18="","",IF(E18="over",IF(F18>D18,1,IF(F18<D18,0,"push")),IF(F18<D18,1,IF(F18>D18,0,"push")))) | I18: =IF(G18="push",0,IF(G18=1,H18*(picks!Q1^(1/2)-1),IF(G18=0,-H18,"")))
G19: =IF(F19="","",IF(E19="over",IF(F19>D19,1,IF(F19<D19,0,"push")),IF(F19<D19,1,IF(F19>D19,0,"push")))) | I19: =IF(G19="push",0,IF(G19=1,H19*(picks!Q1^(1/2)-1),IF(G19=0,-H19,"")))
G20: =IF(F20="","",IF(E20="over",IF(F20>D20,1,IF(F20<D20,0,"push")),IF(F20<D20,1,IF(F20>D20,0,"push")))) | I20: =IF(G20="push",0,IF(G20=1,H20*(picks!Q1^(1/2)-1),IF(G20=0,-H20,"")))
G21: =IF(F21="","",IF(E21="over",IF(F21>D21,1,IF(F21<D21,0,"push")),IF(F21<D21,1,IF(F21>D21,0,"push")))) | I21: =IF(G21="push",0,IF(G21=1,H21*(picks!Q1^(1/2)-1),IF(G21=0,-H21,"")))
G22: =IF(F22="","",IF(E22="over",IF(F22>D22,1,IF(F22<D22,0,"push")),IF(F22<D22,1,IF(F22>D22,0,"push")))) | I22: =IF(G22="push",0,IF(G22=1,H22*(picks!Q1^(1/2)-1),IF(G22=0,-H22,"")))
G23: =IF(F23="","",IF(E23="over",IF(F23>D23,1,IF(F23<D23,0,"push")),IF(F23<D23,1,IF(F23>D23,0,"push")))) | I23: =IF(G23="push",0,IF(G23=1,H23*(picks!Q1^(1/2)-1),IF(G23=0,-H23,"")))
G24: =IF(F24="","",IF(E24="over",IF(F24>D24,1,IF(F24<D24,0,"push")),IF(F24<D24,1,IF(F24>D24,0,"push")))) | I24: =IF(G24="push",0,IF(G24=1,H24*(picks!Q1^(1/2)-1),IF(G24=0,-H24,"")))
G25: =IF(F25="","",IF(E25="over",IF(F25>D25,1,IF(F25<D25,0,"push")),IF(F25<D25,1,IF(F25>D25,0,"push")))) | I25: =IF(G25="push",0,IF(G25=1,H25*(picks!Q1^(1/2)-1),IF(G25=0,-H25,"")))
G26: =IF(F26="","",IF(E26="over",IF(F26>D26,1,IF(F26<D26,0,"push")),IF(F26<D26,1,IF(F26>D26,0,"push")))) | I26: =IF(G26="push",0,IF(G26=1,H26*(picks!Q1^(1/2)-1),IF(G26=0,-H26,"")))
G27: =IF(F27="","",IF(E27="over",IF(F27>D27,1,IF(F27<D27,0,"push")),IF(F27<D27,1,IF(F27>D27,0,"push")))) | I27: =IF(G27="push",0,IF(G27=1,H27*(picks!Q1^(1/2)-1),IF(G27=0,-H27,"")))
G28: =IF(F28="","",IF(E28="over",IF(F28>D28,1,IF(F28<D28,0,"push")),IF(F28<D28,1,IF(F28>D28,0,"push")))) | I28: =IF(G28="push",0,IF(G28=1,H28*(picks!Q1^(1/2)-1),IF(G28=0,-H28,"")))
G29: =IF(F29="","",IF(E29="over",IF(F29>D29,1,IF(F29<D29,0,"push")),IF(F29<D29,1,IF(F29>D29,0,"push")))) | I29: =IF(G29="push",0,IF(G29=1,H29*(picks!Q1^(1/2)-1),IF(G29=0,-H29,"")))
G30: =IF(F30="","",IF(E30="over",IF(F30>D30,1,IF(F30<D30,0,"push")),IF(F30<D30,1,IF(F30>D30,0,"push")))) | I30: =IF(G30="push",0,IF(G30=1,H30*(picks!Q1^(1/2)-1),IF(G30=0,-H30,"")))
G31: =IF(F31="","",IF(E31="over",IF(F31>D31,1,IF(F31<D31,0,"push")),IF(F31<D31,1,IF(F31>D31,0,"push")))) | I31: =IF(G31="push",0,IF(G31=1,H31*(picks!Q1^(1/2)-1),IF(G31=0,-H31,"")))
G32: =IF(F32="","",IF(E32="over",IF(F32>D32,1,IF(F32<D32,0,"push")),IF(F32<D32,1,IF(F32>D32,0,"push")))) | I32: =IF(G32="push",0,IF(G32=1,H32*(picks!Q1^(1/2)-1),IF(G32=0,-H32,"")))
G33: =IF(F33="","",IF(E33="over",IF(F33>D33,1,IF(F33<D33,0,"push")),IF(F33<D33,1,IF(F33>D33,0,"push")))) | I33: =IF(G33="push",0,IF(G33=1,H33*(picks!Q1^(1/2)-1),IF(G33=0,-H33,"")))
G34: =IF(F34="","",IF(E34="over",IF(F34>D34,1,IF(F34<D34,0,"push")),IF(F34<D34,1,IF(F34>D34,0,"push")))) | I34: =IF(G34="push",0,IF(G34=1,H34*(picks!Q1^(1/2)-1),IF(G34=0,-H34,"")))
G35: =IF(F35="","",IF(E35="over",IF(F35>D35,1,IF(F35<D35,0,"push")),IF(F35<D35,1,IF(F35>D35,0,"push")))) | I35: =IF(G35="push",0,IF(G35=1,H35*(picks!Q1^(1/2)-1),IF(G35=0,-H35,"")))
G36: =IF(F36="","",IF(E36="over",IF(F36>D36,1,IF(F36<D36,0,"push")),IF(F36<D36,1,IF(F36>D36,0,"push")))) | I36: =IF(G36="push",0,IF(G36=1,H36*(picks!Q1^(1/2)-1),IF(G36=0,-H36,"")))
G37: =IF(F37="","",IF(E37="over",IF(F37>D37,1,IF(F37<D37,0,"push")),IF(F37<D37,1,IF(F37>D37,0,"push")))) | I37: =IF(G37="push",0,IF(G37=1,H37*(picks!Q1^(1/2)-1),IF(G37=0,-H37,"")))
G38: =IF(F38="","",IF(E38="over",IF(F38>D38,1,IF(F38<D38,0,"push")),IF(F38<D38,1,IF(F38>D38,0,"push")))) | I38: =IF(G38="push",0,IF(G38=1,H38*(picks!Q1^(1/2)-1),IF(G38=0,-H38,"")))
G39: =IF(F39="","",IF(E39="over",IF(F39>D39,1,IF(F39<D39,0,"push")),IF(F39<D39,1,IF(F39>D39,0,"push")))) | I39: =IF(G39="push",0,IF(G39=1,H39*(picks!Q1^(1/2)-1),IF(G39=0,-H39,"")))
G40: =IF(F40="","",IF(E40="over",IF(F40>D40,1,IF(F40<D40,0,"push")),IF(F40<D40,1,IF(F40>D40,0,"push")))) | I40: =IF(G40="push",0,IF(G40=1,H40*(picks!Q1^(1/2)-1),IF(G40=0,-H40,"")))
...
